Workbook

Sheet Instructions
A1: Quick Start Guide
A3: Step 1: Enter your latest YTD paystub details in the 'Wage Snapshots' tab.
A4: Step 2: Enter your latest YTD brokerage totals in 'Investment Income Snapshots'.
A5: Step 3: (Optional) Enter your 'Prior Year Tax' liability in the Dashboard to enable Safe Harbor targets.
A6: Step 4: (Optional) Enter your estimated 'Itemized Deductions' if you expect to exceed the Standard Deduction.
A7: Step 5: Check the 'PAYMENT ACTION CENTER' on the Dashboard for immediate payment requirements.
A9: Important Notes
A10: 1. Investment Income: Dividends and Interest are automatically projected for the full year based on the current quarter. Capital Gains (Short/Long term) are treated as one-off events and are NOT projected.
A11: 2. HSA (California): HSA contributions are automatically added back to CA state income as they are not deductible in California.
A12: 3. Income Projections: The engine pro-rates your remaining annual income based on the days elapsed since Jan 1. You can adjust these projections by entering values into 'Manual Income Offset' or 'Future Income Weight' in Section 1.5 of the Dashboard.
A13: 4. YTD Methodology: Always use Year-to-Date (YTD) totals from your statements. Overwrite existing rows as new statements arrive.

Sheet Dashboard
A1: Configuration | D1: Estimated Tax Payments Ledger | I1: PAYMENT ACTION CENTER
A2: Filing Status (Single) | B2: Single | D2: Date | E2: Calculated Estimate (Optional) | F2: Actual Payment Made (Required) | G2: Note | I2: FED DUE NOW: | J2: =IFS(B9<=DATE(B8,4,15), C55, B9<=DATE(B8,6,15), C56, B9<=DATE(B8,9,15), C57, TRUE, C58)
A3: Dependents (Under 17) | B3: 0 | D3: =DATE(B8,4,15) | G3: Fed Q1 | I3: BY DEADLINE: | J3: =IFS(B9<=DATE(B8,4,15), "04/15/"&B8, B9<=DATE(B8,6,15), "06/15/"&B8, B9<=DATE(B8,9,15), "09/15/"&B8, TRUE, "01/15/"&(B8+1))
A4: Prior Year Fed Tax (Safe Harbor) | B4: 0 | D4: =DATE(B8,4,15) | G4: CA Q1 | I4: Next FED Target: | J4: =IFS(B9<=DATE(B8,4,15), B55, B9<=DATE(B8,6,15), B56, B9<=DATE(B8,9,15), B57, TRUE, B58)
A5: Prior Year CA Tax (Safe Harbor) | B5: 0 | D5: =DATE(B8,6,15) | G5: Fed Q2 | I5: FED Payments YTD: | J5: =B50
A6: Estimated Fed Itemized Deduction | B6: 0 | D6: =DATE(B8,6,15) | G6: CA Q2 | I6: FED Status: | J6: =IF(J5>=J4, "✅ Met (Surplus: " & TEXT(J5-J4, "$#,##0") & ")", "🔴 Shortfall (" & TEXT(J4-J5, "$#,##0") & ")")
A7: Estimated CA Itemized Deduction | B7: 0 | D7: =DATE(B8,9,15) | G7: Fed Q3
A8: Estimated Tax Year | B8: =IF(AND(MONTH(B9)=1, DAY(B9)<=30), YEAR(B9)-1, YEAR(B9)) | D8: =DATE(B8,9,15) | G8: CA Q3 | I8: CA DUE NOW: | J8: =IFS(B9<=DATE(B8,4,15), C61, B9<=DATE(B8,6,15), C62, B9<=DATE(B8,9,15), C63, TRUE, C64)
A9: Status Date | B9: =TODAY() | D9: =DATE(B8+1,1,15) | G9: Fed Q4 | I9: BY DEADLINE: | J9: =IFS(B9<=DATE(B8,4,15), "04/15/"&B8, B9<=DATE(B8,6,15), "06/15/"&B8, B9<=DATE(B8,9,15), "09/15/"&B8, TRUE, "01/15/"&(B8+1))
D10: =DATE(B8+1,1,15) | G10: CA Q4 | I10: Next CA Target: | J10: =IFS(B9<=DATE(B8,4,15), B61, B9<=DATE(B8,6,15), B62, B9<=DATE(B8,9,15), B63, TRUE, B64)
A11: Projection & Assumptions | I11: CA Payments YTD: | J11: =B52
A12: Manual Income Offset ($) | B12: 0 | I12: CA Status: | J12: =IF(J11>=J10, "✅ Met (Surplus: " & TEXT(J11-J10, "$#,##0") & ")", "🔴 Shortfall (" & TEXT(J10-J11, "$#,##0") & ")")
A13: Future Income Weight (%) | B13: 1
A14: Remaining Year Wage Income | B14: =IF(MAX('Wage Snapshots'!A:A)=0, 0, (SUM('Wage Snapshots'!B:B) / MAX(1, MAX('Wage Snapshots'!A:A) - DATE(B8,1,1))) * (DATE(B8,12,31) - MAX('Wage Snapshots'!A:A)))
A15: Remaining Year Deductions | B15: =IF(MAX('Wage Snapshots'!A:A)=0, 0, (SUM('Wage Snapshots'!C:D) / MAX(1, MAX('Wage Snapshots'!A:A) - DATE(B8,1,1))) * (DATE(B8,12,31) - MAX('Wage Snapshots'!A:A))) | I15: TAX DIAGNOSTICS
A16: Remaining Year Interest and Dividends | B16: =SUM('Investment Income Snapshots'!C:C) * ( (4 / ROUNDUP(MONTH(B9)/3, 0)) - 1 ) | I16: Fed Target Method: | J16: =IF(B4=0, "90% Forecast", IF(B46*0.9 < B4*1.1, "90% Forecast", "110% Safe Harbor"))
A17: Consolidated Income Projection | I17: CA Target Method: | J17: =IF(B5=0, "80% Forecast", IF(B37*0.8 < B5*1.1, "80% Forecast", "110% Safe Harbor"))
A18: Total Projected Wage Income | B18: =SUM('Wage Snapshots'!B:B) + (B14 * B13) + B12 | I18: Effective Fed Rate: | J18: =B46 / MAX(1, B23)
A19: Federal W-2 State Wages | B19: =B18 - SUM('Wage Snapshots'!C:D) - (B15 * B13) | I19: Effective CA Rate: | J19: =B37 / MAX(1, B23)
A20: CA W-2 State Wages | B20: =B18 - SUM('Wage Snapshots'!C:C) - (SUM('Wage Snapshots'!C:C)/MAX(1, SUM('Wage Snapshots'!C:D))) * B15 * B13 | I20: Marginal Fed Bracket: | J20: =XLOOKUP(B28, FILTER('Tax Constants'!C3:C30, 'Tax Constants'!B3:B30=B2), FILTER('Tax Constants'!E3:E30, 'Tax Constants'!B3:B30=B2), 0, -1)
A21: Investment Ordinary (Div/Int + STG) | B21: =SUM('Investment Income Snapshots'!C:C) + B16 + SUM('Investment Income Snapshots'!D:D) | I21: Marginal CA Bracket: | J21: =XLOOKUP(B34, FILTER('Tax Constants'!C49:C84, 'Tax Constants'!B49:B84=B2), FILTER('Tax Constants'!E49:E84, 'Tax Constants'!B49:B84=B2), 0, -1)
A22: Investment Preferential (LTG Only) | B22: =SUM('Investment Income Snapshots'!E:E) | I22: Deduction Applied: | J22: =IF(B6>XLOOKUP(B2, 'Tax Constants'!B3:B30, 'Tax Constants'!F3:F30, 0), "ITEMIZED", "STANDARD")
A23: Total Projected Federal AGI | B23: =B19 + B21 + B22 | I23: Bracket Year: | J23: 2025
A24: Total Projected CA AGI | B24: =B20 + B21 + B22
I25: ACTIVE WARNINGS
A26: Federal Tax Calculation | I26: Stale Snapshots: | J26: =IF(OR(MAX('Wage Snapshots'!A:A)=0, (B9 - MAX('Wage Snapshots'!A:A)) > 30), "🔴 !!! 30+ DAYS OLD !!!", "OK")
A27: Deduction Applied (Max Std/Item) | B27: =MAX(XLOOKUP(B2, 'Tax Constants'!B3:B30, 'Tax Constants'!F3:F30, 0), B6) | I27: Prior Year Data: | J27: =IF(B4=0, "🔴 WARNING: FED MISSING", "OK")
A28: Ordinary Taxable Income | B28: =MAX(0, B23 - B27 - B22) | I28: HSA Verification (CA): | J28: =IF(SUM('Wage Snapshots'!D:D)=0, "✅ No HSA Detected", IF(B20=B19, "🔴 ERR: HSA NOT ADDED TO CA", "✅ HSA Corrected (CA)"))
A29: Ordinary Income Tax | B29: =XLOOKUP(B28, FILTER('Tax Constants'!C3:C30, 'Tax Constants'!B3:B30=B2), FILTER('Tax Constants'!D3:D30, 'Tax Constants'!B3:B30=B2), 0, -1) + (B28 - XLOOKUP(B28, FILTER('Tax Constants'!C3:C30, 'Tax Constants'!B3:B30=B2), FILTER('Tax Constants'!C3:C30, 'Tax Constants'!B3:B30=B2), 0, -1)) * XLOOKUP(B28, FILTER('Tax Constants'!C3:C30, 'Tax Constants'!B3:B30=B2), FILTER('Tax Constants'!E3:E30, 'Tax Constants'!B3:B30=B2), 0, -1) | I29: Fed Brackets Stale: | J29: =IF(B8 > J23, "⚠️ FED STALE: "&B8&" brackets missing, using 2025 instead", "OK")
A30: Capital Gains Tax | B30: =IF(B22>0, B22 * XLOOKUP(B28+B22, FILTER('Tax Constants'!C34:C45, 'Tax Constants'!B34:B45=B2), FILTER('Tax Constants'!D34:D45, 'Tax Constants'!B34:B45=B2), 0, -1), 0) | I30: CA Brackets Stale: | J30: =IF(B8 > J23, "⚠️ CA STALE: "&B8&" brackets missing, using 2025 instead", "OK")
A32: CA Tax Calculation
A33: CA Deduction Applied | B33: =MAX(XLOOKUP(B2, 'Tax Constants'!B49:B84, 'Tax Constants'!F49:F84, 0), B7)
A34: CA Taxable Income | B34: =MAX(0, B24 - B33)
A35: CA Regular Tax | B35: =XLOOKUP(B34, FILTER('Tax Constants'!C49:C84, 'Tax Constants'!B49:B84=B2), FILTER('Tax Constants'!D49:D84, 'Tax Constants'!B49:B84=B2), 0, -1) + (B34 - XLOOKUP(B34, FILTER('Tax Constants'!C49:C84, 'Tax Constants'!B49:B84=B2), FILTER('Tax Constants'!C49:C84, 'Tax Constants'!B49:B84=B2), 0, -1)) * XLOOKUP(B34, FILTER('Tax Constants'!C49:C84, 'Tax Constants'!B49:B84=B2), FILTER('Tax Constants'!E49:E84, 'Tax Constants'!B49:B84=B2), 0, -1)
A36: CA MH Surcharge (1%) | B36: =IF(B34 > 1000000, (B34 - 1000000) * 0.01, 0)
A37: Total CA Liability | B37: =B35 + B36
A39: Final Liability & Surtaxes
A40: NIIT Threshold | B40: =XLOOKUP(B2, 'Tax Constants'!B88:B91, 'Tax Constants'!C88:C91, 200000)
A41: NIIT (Fed) | B41: =IF(B23 > B40, 0.038 * MIN(B23-B40, B21+B22), 0)
A42: Addl Medicare Threshold | B42: =XLOOKUP(B2, 'Tax Constants'!B88:B91, 'Tax Constants'!D88:D91, 200000)
...

Sheet Investment Income Snapshots
A1: Quarter | B1: Broker | C1: Dividends & Interest | D1: Short-Term Gains | E1: Long-Term Gains

Sheet Wage Snapshots
A1: Date | B1: Gross W-2 Income | C1: Pre-tax Deductions | D1: HSA Contributions | E1: Fed Tax Withheld | F1: CA Tax Withheld | G1: FICA/Med/SDI

Sheet Tax Constants
A1: Table A: Federal Brackets (Ordinary Income)
A2: Year | B2: Status | C2: Bracket Floor | D2: Base Tax | E2: Marginal Rate | F2: Standard Deduction
A3: 2025 | B3: Single | C3: 0 | D3: 0 | E3: 0.1 | F3: 15000
A4: 2025 | B4: Single | C4: 11925 | D4: 1192.5 | E4: 0.12 | F4: 15000
A5: 2025 | B5: Single | C5: 48475 | D5: 5578.5 | E5: 0.22 | F5: 15000
A6: 2025 | B6: Single | C6: 103350 | D6: 17651 | E6: 0.24 | F6: 15000
A7: 2025 | B7: Single | C7: 197300 | D7: 40199 | E7: 0.32 | F7: 15000
A8: 2025 | B8: Single | C8: 250525 | D8: 57231 | E8: 0.35 | F8: 15000
A9: 2025 | B9: Single | C9: 626350 | D9: 188770 | E9: 0.37 | F9: 15000
A10: 2025 | B10: MFJ | C10: 0 | D10: 0 | E10: 0.1 | F10: 30000
A11: 2025 | B11: MFJ | C11: 23850 | D11: 2385 | E11: 0.12 | F11: 30000
A12: 2025 | B12: MFJ | C12: 96950 | D12: 11157 | E12: 0.22 | F12: 30000
A13: 2025 | B13: MFJ | C13: 206700 | D13: 35302 | E13: 0.24 | F13: 30000
A14: 2025 | B14: MFJ | C14: 394600 | D14: 80398 | E14: 0.32 | F14: 30000
... A30: 2025 | B30: HoH | C30: 626350 | D30: 187031.5 | E30: 0.37 | F30: 22500
A32: Table B: Federal Capital Gains Brackets
A33: Year | B33: Status | C33: Bracket Floor | D33: LTCG Rate
A34: 2025 | B34: Single | C34: 0 | D34: 0
A35: 2025 | B35: Single | C35: 47025 | D35: 0.15
A36: 2025 | B36: Single | C36: 518900 | D36: 0.2
A37: 2025 | B37: MFJ | C37: 0 | D37: 0
A38: 2025 | B38: MFJ | C38: 96700 | D38: 0.15
A39: 2025 | B39: MFJ | C39: 600050 | D39: 0.2
A40: 2025 | B40: MFS | C40: 0 | D40: 0
A41: 2025 | B41: MFS | C41: 48350 | D41: 0.15
A42: 2025 | B42: MFS | C42: 300000 | D42: 0.2
A43: 2025 | B43: HoH | C43: 0 | D43: 0
A44: 2025 | B44: HoH | C44: 64750 | D44: 0.15
A45: 2025 | B45: HoH | C45: 566700 | D45: 0.2
A47: Table C: California FTB Brackets
A48: Year | B48: Status | C48: Bracket Floor | D48: Base Tax | E48: Marginal Rate | F48: Standard Deduction | G48: MH Surcharge Floor
A49: 2025 | B49: Single | C49: 0 | D49: 0 | E49: 0.01 | F49: 5706 | G49: 1000000
A50: 2025 | B50: Single | C50: 11079 | D50: 110.79 | E50: 0.02 | F50: 5706 | G50: 1000000
A51: 2025 | B51: Single | C51: 26264 | D51: 414.49 | E51: 0.04 | F51: 5706 | G51: 1000000
A52: 2025 | B52: Single | C52: 41452 | D52: 1022.01 | E52: 0.06 | F52: 5706 | G52: 1000000
A53: 2025 | B53: Single | C53: 57542 | D53: 1987.41 | E53: 0.08 | F53: 5706 | G53: 1000000
A54: 2025 | B54: Single | C54: 72724 | D54: 3201.97 | E54: 0.093 | F54: 5706 | G54: 1000000
A55: 2025 | B55: Single | C55: 371479 | D55: 31036.19 | E55: 0.103 | F55: 5706 | G55: 1000000
A56: 2025 | B56: Single | C56: 445771 | D56: 38688.19 | E56: 0.113 | F56: 5706 | G56: 1000000
A57: 2025 | B57: Single | C57: 742953 | D57: 72269.75 | E57: 0.123 | F57: 5706 | G57: 1000000
...

Sheet Parsing Instructions for Agents
A1: PROMPT INSTRUCTIONS
A2: Copy and paste the text below into an AI (like Gemini, ChatGPT, or Claude) along with your paystubs or brokerage statements to automatically extract the data for this workbook.
A4: # Role & Objective Your purpose is to parse unstructured text, images, or PDFs of paystubs and brokerage statements provided by the user, and format the extracted data into precise, tab-separated tables. These tables are designed to be copied and pasted directly into a master Tax Projection Excel workbook. Do not add any conversational filler, introductory text, or concluding remarks. Output **only** the requested tables unless I ask you a question. Do not reference any data inside your project directory, if one exists. Don't store state outside the context window. You are just a function which translates provided uploaded inputs into outputs. --- # Formatting Rules 1. **Output Format**: Use a Markdown table format. Ensure that columns align correctly. Do not use comma-separated values (CSV). Use numerical formats without commas or dollar signs (e.g., use `1500.50` instead of `$1,500.50`). 2. **Missing Values**: If a value is not present on the document, output `0`. Do not leave it blank or use "N/A". 3. **Detection**: Automatically detect whether the provided document is a Paystub or a Brokerage Statement and output the corresponding table. If the user provides both, output both under their respective headers: `### Wage Snapshots` and `### Investment Income Snapshots`. --- # Schema 1: Wage Snapshots (Paystubs) If the document is a paystub, RSU release confirmation, or W-2 income event, extract the data into the following columns exactly as defined: | Date | Gross W-2 Income | Pre-tax Deductions | HSA Contributions | Fed Tax Withheld | CA Tax Withheld | FICA/Med/SDI | |---|---|---|---|---|---|---| **Extraction Logic for Wage Snapshots:** * **Date**: The date of the paystub or vest event (Format: MM/DD/YYYY). * **Gross W-2 Income**: The **Year-to-Date (YTD)** gross pay, combining base salary, bonus payout, and/or the total taxable value of RSU vests up to this date. * **Pre-tax Deductions**: The sum of all **YTD** pre-tax deductions (e.g., Traditional 401k, FSA, Health/Dental/Vision premiums). **CRITICAL IMPERATIVE**: Do **not** include HSA contributions in this sum. * **HSA Contributions**: The **YTD** pre-tax HSA contribution amount. (This must be isolated because California does not recognize HSA deductions). * **Fed Tax Withheld**: The **YTD** Federal Income Tax withheld. * **CA Tax Withheld**: The **YTD** California State Income Tax withheld. * **FICA/Med/SDI**: The sum of **YTD** Social Security (OASDI), Medicare, and CA State Disability Insurance (CA SDI) withheld. --- # Schema 2: Investment Income Snapshots (Brokerage Statements) If the document is a 1099-DIV, 1099-B, or a quarterly consolidated brokerage statement, extract the data into the following columns exactly as defined: | Quarter | Entity | Dividends & Interest | Short-Term Gains | Long-Term Gains | |---|---|---|---|---| **Extraction Logic for Investment Income Snapshots:** * **Quarter**: The most recent quarter the statement covers (e.g., `Q1`, `Q2`, `Q3`, `Q4`, or `Annual`). * **Entity**: The name of the brokerage or issuing institution (e.g., `Schwab`, `E-Trade`, `Fidelity`). * **Dividends & Interest**: **Year-to-Date (YTD)** total of all dividends (Qualified + Ordinary) and all taxable interest. Combine these into a single sum. * **Short-Term Gains**: **Year-to-Date (YTD)** net short-term capital gains realized. * **Long-Term Gains**: **Year-to-Date (YTD)** net long-term capital gains realized. THESE NUMBERS ARE VERY IMPORTANT. CHECK YOUR WORK TWICE. DO NOT HALLUCINATE DO NOT REFERENCE INPUT DATA OUTSIDE OF YOUR THREAD CONTEXT WINDOW. TREAT YOURSELF AS A FUNCTION WHICH TRANSLATES UPLOADED INPUTS INTO OUTPUTS
