Workbook

Sheet Instructions
A1: ⚠️ DISCLAIMER: For Informational Purposes Only
A2: This tool is intended for informational and educational purposes only and does not constitute professional tax, legal, or accounting advice. You should consult with a qualified tax professional before making financial decisions or filing your returns. The author assumes no liability for errors, omissions, or penalties resulting from the use of this workbook.
A4: Quick Start Guide
A5: Step 1: Enter your latest YTD paystub details in the 'Wage Snapshots' tab.
A6: Step 2: Enter your latest YTD brokerage totals in 'Investment Income Snapshots'.
A7: Step 3: (Optional) Enter your 'Prior Year Tax' liability in the Dashboard to enable Safe Harbor targets.
A8: Step 4: (Optional) Enter your estimated 'Itemized Deductions' if you expect to exceed the Standard Deduction.
A9: Step 5: Check the 'PAYMENT ACTION CENTER' on the Dashboard for immediate payment requirements.
A11: Important Notes
A12: 1. Investment Income: Dividends and Interest are automatically projected for the full year based on the current quarter. Capital Gains (Short/Long term) are treated as one-off events and are NOT projected.
A13: 2. HSA (California): HSA contributions are automatically added back to CA state income as they are not deductible in California.
A14: 3. Income Projections: The engine pro-rates your remaining annual income based on the days elapsed since Jan 1. You can adjust these projections by entering values into 'Manual Income Offset' or 'Future Income Weight' in Section 1.5 of the Dashboard.
A15: 4. YTD Methodology: Always use Year-to-Date (YTD) totals from your statements. Overwrite existing rows as new statements arrive.

Sheet Dashboard
A1: Configuration | D1: Estimated Tax Payments Ledger | I1: PAYMENT ACTION CENTER
A2: Filing Status (Single) | B2: Single | D2: Date | E2: Calculated Estimate (Optional) | F2: Actual Payment Made (Required) | G2: Note | I2: FED DUE NOW: | J2: =IFS(B9<=DATE(B8,4,15), C58, B9<=DATE(B8,6,15), C59, B9<=DATE(B8,9,15), C60, TRUE, C61)
A3: Dependents (Under 17) | B3: 0 | D3: =DATE(B8,4,15) | G3: Fed Q1 | I3: BY DEADLINE: | J3: =IFS(B9<=DATE(B8,4,15), "04/15/"&B8, B9<=DATE(B8,6,15), "06/15/"&B8, B9<=DATE(B8,9,15), "09/15/"&B8, TRUE, "01/15/"&(B8+1))
A4: Prior Year Fed Tax (Safe Harbor) | B4: 0 | I4: Next FED Target: | J4: =IFS(B9<=DATE(B8,4,15), B58, B9<=DATE(B8,6,15), B59, B9<=DATE(B8,9,15), B60, TRUE, B61)
D5: =DATE(B8,6,15) | G5: Fed Q2 | I5: FED Payments YTD: | J5: =B52
A6: Estimated Fed Itemized Deduction | B6: 0 | I6: FED Status: | J6: =IF(J5>=J4, "✅ Met (Surplus: " & TEXT(J5-J4, "$#,##0") & ")", "🔴 Shortfall (" & TEXT(J4-J5, "$#,##0") & ")")
D7: =DATE(B8,9,15) | G7: Fed Q3
A8: Estimated Tax Year | B8: =IF(AND(MONTH(B9)=1, DAY(B9)<=30), YEAR(B9)-1, YEAR(B9))
A9: Filing (Current) Date | B9: =TODAY() | D9: =DATE(B8+1,1,15) | G9: Fed Q4
A10: Inferred Estimated Tax Quarter | B10: =MIN(4, MAX(1, ROUNDUP((MONTH(B9)-1)/3, 0)))
A12: Projection & Assumptions
A13: Manual Income Offset ($) | B13: 0
A14: Future Income Weight (%) | B14: 1
A15: Remaining Year Wage Income | B15: =IF(MAX('Wage Snapshots'!A:A)=0, 0, (SUM('Wage Snapshots'!B:B) / MAX(1, MAX('Wage Snapshots'!A:A) - DATE(B8,1,1))) * (DATE(B8,12,31) - MAX('Wage Snapshots'!A:A))) | I15: TAX DIAGNOSTICS
A16: Remaining Year Deductions | B16: =IF(MAX('Wage Snapshots'!A:A)=0, 0, (SUM('Wage Snapshots'!C:D) / MAX(1, MAX('Wage Snapshots'!A:A) - DATE(B8,1,1))) * (DATE(B8,12,31) - MAX('Wage Snapshots'!A:A))) | I16: Fed Target Method: | J16: =IF(B4=0, "90% Forecast", IF(B48*0.9 < B4*1.1, "90% Forecast", "110% Safe Harbor"))
A17: Remaining Year Interest and Dividends | B17: =SUM('Investment Income Snapshots'!C:C) * ( (4 / B10) - 1 )
I18: Effective Fed Rate: | J18: =B48 / MAX(1, B25)
A19: Consolidated Income Projection
A20: Total Projected Wage Income | B20: =SUM('Wage Snapshots'!B:B) + (B15 * B14) + B13 | I20: Marginal Fed Bracket: | J20: =XLOOKUP(B30, FILTER('Tax Constants'!C3:C30, 'Tax Constants'!B3:B30=B2), FILTER('Tax Constants'!E3:E30, 'Tax Constants'!B3:B30=B2), 0, -1)
A21: Federal W-2 State Wages | B21: =B20 - SUM('Wage Snapshots'!C:D) - (B16 * B14)
I22: Deduction Applied: | J22: =IF(B6>XLOOKUP(B2, 'Tax Constants'!B3:B30, 'Tax Constants'!F3:F30, 0), "ITEMIZED", "STANDARD")
A23: Investment Ordinary (Div/Int + STG) | B23: =SUM('Investment Income Snapshots'!C:C) + B17 + SUM('Investment Income Snapshots'!D:D) | I23: Bracket Year: | J23: 2025
A24: Investment Preferential (LTG Only) | B24: =SUM('Investment Income Snapshots'!E:E) | I24: Inferred Quarter: | J24: =B10
A25: Total Projected Federal AGI | B25: =B21 + B23 + B24
I26: ACTIVE WARNINGS
I27: Stale Snapshots: | J27: =IF(OR(MAX('Wage Snapshots'!A:A)=0, (B9 - MAX('Wage Snapshots'!A:A)) > 30), "🔴 !!! 30+ DAYS OLD !!!", "OK")
A28: Federal Tax Calculation | I28: Prior Year Data: | J28: =IF(B4=0, "🔴 WARNING: FED MISSING", "OK")
A29: Deduction Applied (Max Std/Item) | B29: =MAX(XLOOKUP(B2, 'Tax Constants'!B3:B30, 'Tax Constants'!F3:F30, 0), B6)
A30: Ordinary Taxable Income | B30: =MAX(0, B25 - B29 - B24) | I30: Fed Brackets Stale: | J30: =IF(B8 > J23, "⚠️ FED STALE: "&B8&" brackets missing, using 2025 instead", "OK")
A31: Ordinary Income Tax | B31: =XLOOKUP(B30, FILTER('Tax Constants'!C3:C30, 'Tax Constants'!B3:B30=B2), FILTER('Tax Constants'!D3:D30, 'Tax Constants'!B3:B30=B2), 0, -1) + (B30 - XLOOKUP(B30, FILTER('Tax Constants'!C3:C30, 'Tax Constants'!B3:B30=B2), FILTER('Tax Constants'!C3:C30, 'Tax Constants'!B3:B30=B2), 0, -1)) * XLOOKUP(B30, FILTER('Tax Constants'!C3:C30, 'Tax Constants'!B3:B30=B2), FILTER('Tax Constants'!E3:E30, 'Tax Constants'!B3:B30=B2), 0, -1)
A32: Capital Gains Tax | B32: =IF(B24>0, B24 * XLOOKUP(B30+B24, FILTER('Tax Constants'!C34:C45, 'Tax Constants'!B34:B45=B2), FILTER('Tax Constants'!D34:D45, 'Tax Constants'!B34:B45=B2), 0, -1), 0) | I32: Filing Date Validity: | J32: =IF(OR(B9 < DATE(B8,1,1), B9 > DATE(B8+1,1,30)), "🔴 ERR: DATE OUT OF RANGE", "OK")
I33: HOH Dependents: | J33: =IF(AND(B2="HoH", B3=0), "⚠️ Head of Household with 0 dependents is unusual", "OK")
A41: Final Liability & Surtaxes
A42: NIIT Threshold | B42: =XLOOKUP(B2, 'Tax Constants'!B88:B91, 'Tax Constants'!C88:C91, 200000)
A43: NIIT (Fed) | B43: =IF(B25 > B42, 0.038 * MIN(B25-B42, B23+B24), 0)
A44: Addl Medicare Threshold | B44: =XLOOKUP(B2, 'Tax Constants'!B88:B91, 'Tax Constants'!D88:D91, 200000)
A45: Addl Medicare (Fed) | B45: =IF(B20 > B44, 0.009 * (B20-B44), 0)
A46: CTC Phaseout Start | B46: =XLOOKUP(B2, 'Tax Constants'!B88:B91, 'Tax Constants'!E88:E91, 200000)
A47: Child Tax Credit | B47: =IF(B25 > B46, MAX(0, (B3*2000)-((B25-B46)/1000)*50), B3*2000)
A48: Total Federal Liability | B48: =B31 + B32 + B43 + B45 - B47
...

Sheet Investment Income Snapshots
A1: Quarter | B1: Broker | C1: Dividends & Interest | D1: Short-Term Gains | E1: Long-Term Gains

Sheet Wage Snapshots
A1: Date | B1: Gross W-2 Income | C1: Pre-tax Deductions | D1: HSA Contributions | E1: Fed Tax Withheld | F1: CA Tax Withheld | G1: FICA/Med/SDI

Sheet Tax Constants
A1: Table A: Federal Brackets (Ordinary Income)
A2: Year | B2: Status | C2: Bracket Floor | D2: Base Tax | E2: Marginal Rate | F2: Standard Deduction
A3: 2025 | B3: Single | C3: 0 | D3: 0 | E3: 0.1 | F3: 15000
A4: 2025 | B4: Single | C4: 11925 | D4: 1192.5 | E4: 0.12 | F4: 15000
A5: 2025 | B5: Single | C5: 48475 | D5: 5578.5 | E5: 0.22 | F5: 15000
A6: 2025 | B6: Single | C6: 103350 | D6: 17651 | E6: 0.24 | F6: 15000
A7: 2025 | B7: Single | C7: 197300 | D7: 40199 | E7: 0.32 | F7: 15000
A8: 2025 | B8: Single | C8: 250525 | D8: 57231 | E8: 0.35 | F8: 15000
A9: 2025 | B9: Single | C9: 626350 | D9: 188770 | E9: 0.37 | F9: 15000
A10: 2025 | B10: MFJ | C10: 0 | D10: 0 | E10: 0.1 | F10: 30000
A11: 2025 | B11: MFJ | C11: 23850 | D11: 2385 | E11: 0.12 | F11: 30000
A12: 2025 | B12: MFJ | C12: 96950 | D12: 11157 | E12: 0.22 | F12: 30000
A13: 2025 | B13: MFJ | C13: 206700 | D13: 35302 | E13: 0.24 | F13: 30000
A14: 2025 | B14: MFJ | C14: 394600 | D14: 80398 | E14: 0.32 | F14: 30000
... A30: 2025 | B30: HoH | C30: 626350 | D30: 187031.5 | E30: 0.37 | F30: 22500
A32: Table B: Federal Capital Gains Brackets
A33: Year | B33: Status | C33: Bracket Floor | D33: LTCG Rate
A34: 2025 | B34: Single | C34: 0 | D34: 0
A35: 2025 | B35: Single | C35: 47025 | D35: 0.15
A36: 2025 | B36: Single | C36: 518900 | D36: 0.2
A37: 2025 | B37: MFJ | C37: 0 | D37: 0
A38: 2025 | B38: MFJ | C38: 96700 | D38: 0.15
A39: 2025 | B39: MFJ | C39: 600050 | D39: 0.2
A40: 2025 | B40: MFS | C40: 0 | D40: 0
A41: 2025 | B41: MFS | C41: 48350 | D41: 0.15
A42: 2025 | B42: MFS | C42: 300000 | D42: 0.2
A43: 2025 | B43: HoH | C43: 0 | D43: 0
A44: 2025 | B44: HoH | C44: 64750 | D44: 0.15
A45: 2025 | B45: HoH | C45: 566700 | D45: 0.2
A47: Table D: Surtaxes & Phaseouts
A48: Year | B48: Status | C48: NIIT Threshold | D48: Addl Medicare | E48: CTC Phaseout Start
A49: 2025 | B49: Single | C49: 200000 | D49: 200000 | E49: 200000
A50: 2025 | B50: MFJ | C50: 250000 | D50: 250000 | E50: 400000
A51: 2025 | B51: MFS | C51: 125000 | D51: 125000 | E51: 200000
A52: 2025 | B52: HoH | C52: 200000 | D52: 200000 | E52: 200000

Sheet Parsing Instructions for Agents
A1: PROMPT INSTRUCTIONS
A2: Copy and paste the text below into an AI (like Gemini, ChatGPT, or Claude) along with your paystubs or brokerage statements to automatically extract the data for this workbook.
A4: # Role & Objective Your purpose is to parse unstructured text, images, or PDFs of paystubs and brokerage statements provided by the user, and format the extracted data into precise, tab-separated tables. These tables are designed to be copied and pasted directly into a master Tax Projection Excel workbook. Do not add any conversational filler, introductory text, or concluding remarks. Output **only** the requested tables unless I ask you a question. Do not reference any data inside your project directory, if one exists. Don't store state outside the context window. You are just a function which translates provided uploaded inputs into outputs. --- # Formatting Rules 1. **Output Format**: Use a Markdown table format. Ensure that columns align correctly. Do not use comma-separated values (CSV). Use numerical formats without commas or dollar signs (e.g., use `1500.50` instead of `$1,500.50`). 2. **Missing Values**: If a value is not present on the document, output `0`. Do not leave it blank or use "N/A". 3. **Detection**: Automatically detect whether the provided document is a Paystub or a Brokerage Statement and output the corresponding table. If the user provides both, output both under their respective headers: `### Wage Snapshots` and `### Investment Income Snapshots`. --- # Schema 1: Wage Snapshots (Paystubs) If the document is a paystub, RSU release confirmation, or W-2 income event, extract the data into the following columns exactly as defined: | Date | Gross W-2 Income | Pre-tax Deductions | HSA Contributions | Fed Tax Withheld | CA Tax Withheld | FICA/Med/SDI | |---|---|---|---|---|---|---| **Extraction Logic for Wage Snapshots:** * **Date**: The date of the paystub or vest event (Format: MM/DD/YYYY). * **Gross W-2 Income**: The **Year-to-Date (YTD)** gross pay, combining base salary, bonus payout, and/or the total taxable value of RSU vests up to this date. * **Pre-tax Deductions**: The sum of all **YTD** pre-tax deductions (e.g., Traditional 401k, FSA, Health/Dental/Vision premiums). **CRITICAL IMPERATIVE**: Do **not** include HSA contributions in this sum. * **HSA Contributions**: The **YTD** pre-tax HSA contribution amount. (This must be isolated because California does not recognize HSA deductions). * **Fed Tax Withheld**: The **YTD** Federal Income Tax withheld. * **CA Tax Withheld**: The **YTD** California State Income Tax withheld. * **FICA/Med/SDI**: The sum of **YTD** Social Security (OASDI), Medicare, and CA State Disability Insurance (CA SDI) withheld. --- # Schema 2: Investment Income Snapshots (Brokerage Statements) If the document is a 1099-DIV, 1099-B, or a quarterly consolidated brokerage statement, extract the data into the following columns exactly as defined: | Quarter | Entity | Dividends & Interest | Short-Term Gains | Long-Term Gains | |---|---|---|---|---| **Extraction Logic for Investment Income Snapshots:** * **Quarter**: The most recent quarter the statement covers (e.g., `Q1`, `Q2`, `Q3`, `Q4`, or `Annual`). * **Entity**: The name of the brokerage or issuing institution (e.g., `Schwab`, `E-Trade`, `Fidelity`). * **Dividends & Interest**: **Year-to-Date (YTD)** total of all dividends (Qualified + Ordinary) and all taxable interest. Combine these into a single sum. * **Short-Term Gains**: **Year-to-Date (YTD)** net short-term capital gains realized. * **Long-Term Gains**: **Year-to-Date (YTD)** net long-term capital gains realized. THESE NUMBERS ARE VERY IMPORTANT. CHECK YOUR WORK TWICE. DO NOT HALLUCINATE DO NOT REFERENCE INPUT DATA OUTSIDE OF YOUR THREAD CONTEXT WINDOW. TREAT YOURSELF AS A FUNCTION WHICH TRANSLATES UPLOADED INPUTS INTO OUTPUTS
