Workbook

Sheet Instructions
A1: Universal Tax Orchestrator - Quick Start Guide
A3: Step 1: Enter your latest YTD paystub details in the 'Wage Snapshots' tab.
A4: Step 2: Enter your latest YTD brokerage totals in 'Investment Income Snapshots'.
A5: Step 3: Enter your 'Prior Year Tax' liability in the Dashboard (Section 1) to enable Safe Harbor targets.
A6: Step 4: Check the 'PAYMENT ACTION CENTER' on the Dashboard for immediate payment requirements.
A8: IMPORTANT NOTES & SIMPLIFICATIONS:
A9: 1. Investment Income: All dividends and interest are combined and taxed as Ordinary Income for a safe, conservative projection.
A10: 2. HSA (California): HSA contributions are automatically added back to CA state income as they are not deductible in California.
A11: 3. Burn Rate Projections: The engine pro-rates your remaining annual income based on the days elapsed between Jan 1 and your latest snapshot date.
A12: 4. YTD Methodology: Always use Year-to-Date (YTD) totals from your statements. Overwrite existing rows as new statements arrive.

Sheet Dashboard
A1: Configuration | D1: Estimated Tax Payments Ledger | I1: PAYMENT ACTION CENTER
A2: Filing Status (Single) | B2: Single | D2: Date | E2: Calculated Estimate | F2: Actual Payment Made | G2: Note | I2: FED DUE NOW: | J2: =IFS(B9<=DATE(B8,4,15), C55, B9<=DATE(B8,6,15), C56, B9<=DATE(B8,9,15), C57, TRUE, C58)
A3: Dependents (Under 17) | B3: 0 | D3: 04/15/2026 | G3: Fed Q1 | I3: BY DEADLINE: | J3: =IFS(B9<=DATE(B8,4,15), "04/15/"&B8, B9<=DATE(B8,6,15), "06/15/"&B8, B9<=DATE(B8,9,15), "09/15/"&B8, TRUE, "01/15/"&(B8+1))
A4: Prior Year Fed Tax (Safe Harbor) | B4: 0 | D4: 04/15/2026 | G4: CA Q1 | I4: Next FED Target: | J4: =IFS(B9<=DATE(B8,4,15), B55, B9<=DATE(B8,6,15), B56, B9<=DATE(B8,9,15), B57, TRUE, B58)
A5: Prior Year CA Tax (Safe Harbor) | B5: 0 | D5: 06/15/2026 | G5: Fed Q2 | I5: FED Payments YTD: | J5: =B50
A6: Estimated Fed Itemized Deduction | B6: 0 | D6: 06/15/2026 | G6: CA Q2 | I6: FED Status: | J6: =IF(J5>=J4, "✅ Met (Surplus: " & TEXT(J5-J4, "$#,##0") & ")", "🔴 Shortfall (" & TEXT(J4-J5, "$#,##0") & ")")
A7: Estimated CA Itemized Deduction | B7: 0 | D7: 09/15/2026 | G7: Fed Q3
A8: Tax Year | B8: 2026 | D8: 09/15/2026 | G8: CA Q3 | I8: CA DUE NOW: | J8: =IFS(B9<=DATE(B8,4,15), C61, B9<=DATE(B8,6,15), C62, B9<=DATE(B8,9,15), C63, TRUE, C64)
A9: Status Date | B9: =TODAY() | D9: 01/15/2027 | G9: Fed Q4 | I9: BY DEADLINE: | J9: =IFS(B9<=DATE(B8,4,15), "04/15/"&B8, B9<=DATE(B8,6,15), "06/15/"&B8, B9<=DATE(B8,9,15), "09/15/"&B8, TRUE, "01/15/"&(B8+1))
D10: 01/15/2027 | G10: CA Q4 | I10: Next CA Target: | J10: =IFS(B9<=DATE(B8,4,15), B61, B9<=DATE(B8,6,15), B62, B9<=DATE(B8,9,15), B63, TRUE, B64)
A11: Projection & Assumptions | I11: CA Payments YTD: | J11: =B52
A12: Manual Income Offset ($) | B12: 0 | I12: CA Status: | J12: =IF(J11>=J10, "✅ Met (Surplus: " & TEXT(J11-J10, "$#,##0") & ")", "🔴 Shortfall (" & TEXT(J10-J11, "$#,##0") & ")")
A13: Future Income Weight (%) | B13: 1
A14: Remaining Year Wage Income | B14: =IF(MAX('Wage Snapshots'!A:A)=0, 0, (SUM('Wage Snapshots'!B:B) / MAX(1, MAX('Wage Snapshots'!A:A) - DATE(B8,1,1))) * (DATE(B8,12,31) - MAX('Wage Snapshots'!A:A)))
A15: Remaining Year Deductions | B15: =IF(MAX('Wage Snapshots'!A:A)=0, 0, (SUM('Wage Snapshots'!C:D) / MAX(1, MAX('Wage Snapshots'!A:A) - DATE(B8,1,1))) * (DATE(B8,12,31) - MAX('Wage Snapshots'!A:A))) | I15: TAX DIAGNOSTICS
I16: Fed Target Method: | J16: =IF(B4=0, "90% Forecast", IF(B46*0.9 < B4*1.1, "90% Forecast", "110% Safe Harbor"))
A17: Consolidated Income Projection | I17: CA Target Method: | J17: =IF(B5=0, "80% Forecast", IF(B37*0.8 < B5*1.1, "80% Forecast", "110% Safe Harbor"))
A18: Total Projected Wage Income | B18: =SUM('Wage Snapshots'!B:B) + (B14 * B13) + B12 | I18: Effective Fed Rate: | J18: =B46 / MAX(1, B23)
A19: Federal W-2 State Wages | B19: =B18 - SUM('Wage Snapshots'!C:D) - (B15 * B13) | I19: Effective CA Rate: | J19: =B37 / MAX(1, B23)
A20: CA W-2 State Wages | B20: =B18 - SUM('Wage Snapshots'!C:C) - (SUM('Wage Snapshots'!C:C)/MAX(1, SUM('Wage Snapshots'!C:D))) * B15 * B13 | I20: Marginal Fed Bracket: | J20: =XLOOKUP(B28, FILTER('Tax Constants'!B3:B30, 'Tax Constants'!A3:A30=B2), FILTER('Tax Constants'!D3:D30, 'Tax Constants'!A3:A30=B2), 0, -1)
A21: Investment Ordinary (Div/Int + STG) | B21: =SUM('Investment Income Snapshots'!C:C) + SUM('Investment Income Snapshots'!D:D) | I21: Marginal CA Bracket: | J21: =XLOOKUP(B34, FILTER('Tax Constants'!B49:B84, 'Tax Constants'!A49:A84=B2), FILTER('Tax Constants'!D49:D84, 'Tax Constants'!A49:A84=B2), 0, -1)
A22: Investment Preferential (LTG Only) | B22: =SUM('Investment Income Snapshots'!E:E) | I22: Deduction Applied: | J22: =IF(B6>XLOOKUP(B2, 'Tax Constants'!A3:A30, 'Tax Constants'!E3:E30, 0), "ITEMIZED", "STANDARD")
A23: Total Projected Federal AGI | B23: =B19 + B21 + B22
A24: Total Projected CA AGI | B24: =B20 + B21 + B22
I25: ACTIVE WARNINGS
A26: Federal Tax Calculation | I26: Stale Snapshots: | J26: =IF(OR(MAX('Wage Snapshots'!A:A)=0, (B9 - MAX('Wage Snapshots'!A:A)) > 30), "!!! 30+ DAYS OLD !!!", "OK")
A27: Deduction Applied (Max Std/Item) | B27: =MAX(XLOOKUP(B2, 'Tax Constants'!A3:A30, 'Tax Constants'!E3:E30, 0), B6) | I27: Prior Year Data: | J27: =IF(B4=0, "WARNING: FED MISSING", "OK")
A28: Ordinary Taxable Income | B28: =MAX(0, B23 - B27 - B22) | I28: HSA Audit (CA): | J28: =IF(B20=B19, "🔴 ERR: HSA NOT ADDED TO CA", "✅ HSA Corrected (CA)")
A29: Ordinary Income Tax | B29: =XLOOKUP(B28, FILTER('Tax Constants'!B3:B30, 'Tax Constants'!A3:A30=B2), FILTER('Tax Constants'!C3:C30, 'Tax Constants'!A3:A30=B2), 0, -1) + (B28 - XLOOKUP(B28, FILTER('Tax Constants'!B3:B30, 'Tax Constants'!A3:A30=B2), FILTER('Tax Constants'!B3:B30, 'Tax Constants'!A3:A30=B2), 0, -1)) * XLOOKUP(B28, FILTER('Tax Constants'!B3:B30, 'Tax Constants'!A3:A30=B2), FILTER('Tax Constants'!D3:D30, 'Tax Constants'!A3:A30=B2), 0, -1)
A30: Capital Gains Tax | B30: =IF(B22>0, B22 * XLOOKUP(B28+B22, FILTER('Tax Constants'!B34:B45, 'Tax Constants'!A34:A45=B2), FILTER('Tax Constants'!C34:C45, 'Tax Constants'!A34:A45=B2), 0, -1), 0)
A32: CA Tax Calculation
A33: CA Deduction Applied | B33: =MAX(XLOOKUP(B2, 'Tax Constants'!A49:A84, 'Tax Constants'!E49:E84, 0), B7)
A34: CA Taxable Income | B34: =MAX(0, B24 - B33)
A35: CA Regular Tax | B35: =XLOOKUP(B34, FILTER('Tax Constants'!B49:B84, 'Tax Constants'!A49:A84=B2), FILTER('Tax Constants'!C49:C84, 'Tax Constants'!A49:A84=B2), 0, -1) + (B34 - XLOOKUP(B34, FILTER('Tax Constants'!B49:B84, 'Tax Constants'!A49:A84=B2), FILTER('Tax Constants'!B49:B84, 'Tax Constants'!A49:A84=B2), 0, -1)) * XLOOKUP(B34, FILTER('Tax Constants'!B49:B84, 'Tax Constants'!A49:A84=B2), FILTER('Tax Constants'!D49:D84, 'Tax Constants'!A49:A84=B2), 0, -1)
A36: CA MH Surcharge (1%) | B36: =IF(B34 > 1000000, (B34 - 1000000) * 0.01, 0)
A37: Total CA Liability | B37: =B35 + B36
A39: Final Liability & Surtaxes
A40: NIIT Threshold | B40: =XLOOKUP(B2, 'Tax Constants'!A88:A91, 'Tax Constants'!B88:B91, 200000)
A41: NIIT (Fed) | B41: =IF(B23 > B40, 0.038 * MIN(B23-B40, B21+B22), 0)
A42: Addl Medicare Threshold | B42: =XLOOKUP(B2, 'Tax Constants'!A88:A91, 'Tax Constants'!C88:C91, 200000)
...

Sheet Investment Income Snapshots
A1: Quarter | B1: Broker | C1: Dividends & Interest | D1: Short-Term Gains | E1: Long-Term Gains

Sheet Wage Snapshots
A1: Date | B1: Gross W-2 Income | C1: Pre-tax Deductions | D1: HSA Contributions | E1: Fed Tax Withheld | F1: CA Tax Withheld | G1: FICA/Med/SDI

Sheet Tax Constants
A1: Table A: Federal Brackets (Ordinary Income - 2026)
A2: Status | B2: Bracket Floor | C2: Base Tax | D2: Marginal Rate | E2: Standard Deduction
A3: Single | B3: 0 | C3: 0 | D3: 0.1 | E3: 15000
A4: Single | B4: 11925 | C4: 1192.5 | D4: 0.12 | E4: 15000
A5: Single | B5: 48475 | C5: 5578.5 | D5: 0.22 | E5: 15000
A6: Single | B6: 103350 | C6: 17651 | D6: 0.24 | E6: 15000
A7: Single | B7: 197300 | C7: 40199 | D7: 0.32 | E7: 15000
A8: Single | B8: 250525 | C8: 57231 | D8: 0.35 | E8: 15000
A9: Single | B9: 626350 | C9: 188770 | D9: 0.37 | E9: 15000
A10: MFJ | B10: 0 | C10: 0 | D10: 0.1 | E10: 30000
A11: MFJ | B11: 23850 | C11: 2385 | D11: 0.12 | E11: 30000
A12: MFJ | B12: 96950 | C12: 11157 | D12: 0.22 | E12: 30000
A13: MFJ | B13: 206700 | C13: 35302 | D13: 0.24 | E13: 30000
A14: MFJ | B14: 394600 | C14: 80398 | D14: 0.32 | E14: 30000
... A30: HoH | B30: 626350 | C30: 187031.5 | D30: 0.37 | E30: 22500
A32: Table B: Federal Capital Gains Brackets (2026)
A33: Status | B33: Bracket Floor | C33: LTCG Rate
A34: Single | B34: 0 | C34: 0
A35: Single | B35: 47025 | C35: 0.15
A36: Single | B36: 518900 | C36: 0.2
A37: MFJ | B37: 0 | C37: 0
A38: MFJ | B38: 96700 | C38: 0.15
A39: MFJ | B39: 600050 | C39: 0.2
A40: MFS | B40: 0 | C40: 0
A41: MFS | B41: 48350 | C41: 0.15
A42: MFS | B42: 300000 | C42: 0.2
A43: HoH | B43: 0 | C43: 0
A44: HoH | B44: 64750 | C44: 0.15
A45: HoH | B45: 566700 | C45: 0.2
A47: Table C: California FTB Brackets (2026)
A48: Status | B48: Bracket Floor | C48: Base Tax | D48: Marginal Rate | E48: Standard Deduction | F48: MH Surcharge Floor
A49: Single | B49: 0 | C49: 0 | D49: 0.01 | E49: 5706 | F49: 1000000
A50: Single | B50: 11079 | C50: 110.79 | D50: 0.02 | E50: 5706 | F50: 1000000
A51: Single | B51: 26264 | C51: 414.49 | D51: 0.04 | E51: 5706 | F51: 1000000
A52: Single | B52: 41452 | C52: 1022.01 | D52: 0.06 | E52: 5706 | F52: 1000000
A53: Single | B53: 57542 | C53: 1987.41 | D53: 0.08 | E53: 5706 | F53: 1000000
A54: Single | B54: 72724 | C54: 3201.97 | D54: 0.093 | E54: 5706 | F54: 1000000
A55: Single | B55: 371479 | C55: 31036.19 | D55: 0.103 | E55: 5706 | F55: 1000000
A56: Single | B56: 445771 | C56: 38688.19 | D56: 0.113 | E56: 5706 | F56: 1000000
A57: Single | B57: 742953 | C57: 72269.75 | D57: 0.123 | E57: 5706 | F57: 1000000
...
